2012-04-16 14:33:43,338 - softwarecenter.ui.gtk3.em - INFO - EM's: 17 15 21
2012-04-16 14:34:12,631 - softwarecenter.backend.reviews - WARNING - Could not get usefulness from server, no username in config file
2012-04-16 14:34:21,852 - softwarecenter.ui.gtk3.utils - INFO - Softwarecenter style provider for ambiance Gtk theme: /usr/share/software-center/ui/gtk3/css/softwarecenter.css
2012-04-16 14:34:53,266 - softwarecenter.ui.gtk3.em - INFO - EM's: 17 15 21
2012-04-16 14:35:34,313 - softwarecenter.fixme - WARNING - logs to the root logger: '('/usr/lib/python2.7/dist-packages/dbus/proxies.py', 406, '_introspect_error_handler')'
2012-04-16 14:35:34,208 - dbus.proxies - ERROR - Introspect error on :1.147:/com/ubuntu/Softwarecenter: dbus.exceptions.DBusException: org.freedesktop.DBus.Error.NoReply: Did not receive a reply. Possible causes include: the remote application did not send a reply, the message bus security policy blocked the reply, the reply timeout expired, or the network connection was broken.
2012-04-16 14:36:09,101 - softwarecenter.ui.gtk3.app - INFO - software-center-agent finished with status 0
2012-04-16 14:36:18,630 - softwarecenter.backend.reviews - WARNING - Could not get usefulness from server, no username in config file
2012-04-16 14:36:21,571 - softwarecenter.ui.gtk3.utils - INFO - Softwarecenter style provider for ambiance Gtk theme: /usr/share/software-center/ui/gtk3/css/softwarecenter.css
2012-04-16 14:37:56,495 - softwarecenter.ui.gtk3.app - INFO - software-center-agent finished with status 0
2012-04-16 14:40:20,477 - softwarecenter.fixme - WARNING - logs to the root logger: '('/usr/lib/python2.7/dist-packages/dbus/connection.py', 218, 'maybe_handle_message')'
2012-04-16 14:40:20,492 - softwarecenter.fixme - WARNING - logs to the root logger: '('/usr/lib/python2.7/dist-packages/dbus/connection.py', 218, 'maybe_handle_message')'
2012-04-16 14:40:20,476 - dbus.connection - ERROR - Exception in handler for D-Bus signal:
Traceback (most recent call last):
  File "/usr/lib/python2.7/dist-packages/dbus/connection.py", line 214, in maybe_handle_message
    self._handler(*args, **kwargs)
  File "/usr/lib/python2.7/dist-packages/dbus/bus.py", line 71, in signal_cb
    callback(new_owner)
  File "/usr/share/software-center/softwarecenter/backend/installbackend_impl/aptd.py", line 148, in _register_active_transactions_watch
    current, queued = apt_daemon.GetActiveTransactions()
  File "/usr/lib/python2.7/dist-packages/dbus/proxies.py", line 143, in __call__
    **keywords)
  File "/usr/lib/python2.7/dist-packages/dbus/connection.py", line 630, in call_blocking
    message, timeout)
DBusException: org.freedesktop.DBus.Error.NoReply: Did not receive a reply. Possible causes include: the remote application did not send a reply, the message bus security policy blocked the reply, the reply timeout expired, or the network connection was broken.
2012-04-16 14:40:20,492 - dbus.connection - ERROR - Exception in handler for D-Bus signal:
Traceback (most recent call last):
  File "/usr/lib/python2.7/dist-packages/dbus/connection.py", line 214, in maybe_handle_message
    self._handler(*args, **kwargs)
  File "/usr/lib/python2.7/dist-packages/dbus/bus.py", line 71, in signal_cb
    callback(new_owner)
  File "/usr/share/software-center/softwarecenter/backend/installbackend_impl/aptd.py", line 148, in _register_active_transactions_watch
    current, queued = apt_daemon.GetActiveTransactions()
  File "/usr/lib/python2.7/dist-packages/dbus/proxies.py", line 143, in __call__
    **keywords)
  File "/usr/lib/python2.7/dist-packages/dbus/connection.py", line 630, in call_blocking
    message, timeout)
DBusException: org.freedesktop.DBus.Error.NoReply: Did not receive a reply. Possible causes include: the remote application did not send a reply, the message bus security policy blocked the reply, the reply timeout expired, or the network connection was broken.
2012-04-16 14:41:02,372 - softwarecenter.backend - WARNING - _on_trans_error: org.freedesktop.DBus.Error.NoReply: Did not receive a reply. Possible causes include: the remote application did not send a reply, the message bus security policy blocked the reply, the reply timeout expired, or the network connection was broken.
2012-04-16 14:58:14,635 - softwarecenter.fixme - WARNING - logs to the root logger: '('/usr/lib/python2.7/dist-packages/dbus/connection.py', 218, 'maybe_handle_message')'
2012-04-16 14:58:14,633 - dbus.connection - ERROR - Exception in handler for D-Bus signal:
Traceback (most recent call last):
  File "/usr/lib/python2.7/dist-packages/dbus/connection.py", line 214, in maybe_handle_message
    self._handler(*args, **kwargs)
  File "/usr/lib/python2.7/dist-packages/dbus/bus.py", line 71, in signal_cb
    callback(new_owner)
  File "/usr/share/software-center/softwarecenter/backend/installbackend_impl/aptd.py", line 148, in _register_active_transactions_watch
    current, queued = apt_daemon.GetActiveTransactions()
  File "/usr/lib/python2.7/dist-packages/dbus/proxies.py", line 143, in __call__
    **keywords)
  File "/usr/lib/python2.7/dist-packages/dbus/connection.py", line 630, in call_blocking
    message, timeout)
DBusException: org.freedesktop.DBus.Error.NoReply: Did not receive a reply. Possible causes include: the remote application did not send a reply, the message bus security policy blocked the reply, the reply timeout expired, or the network connection was broken.
